import { BadRequestError } from '@core/ApiError';

const withErrorHandling = async <T>(callBack: () => Promise<T>): Promise<T> => {
    try {
        return await callBack();
    } catch (error: { code: number; keyPattern: any; keyValue: any } | any) {
        const keys = Object.keys(error.keyPattern);
        const errorMessage: string[] = [];
        switch (error.code) {
            case 11000:
                keys.forEach((key) => {
                    const message = ` "${key}" with "${error.keyValue[key]}" already exist`;
                    errorMessage.push(message);
                });
                throw new BadRequestError(`${errorMessage}`);
            default:
                throw new BadRequestError('Unknown error ');
        }
    }
};

export default withErrorHandling;
